Workbook

Sheet Definitions
B2: Indicator | C2: Definition
B3: Current Electricity Access Rate (%) | C3: Percentage of the total population with access to electricity
B4: Current Urban Electricity Access Rate (%) | C4: Percentage of the urban population with access to electricity.
B5: Current Rural Electricity Access Rate (%) | C5: Percentage of the rural population with access to electricity.
B6: Target Electricity Access Rate by 2030 (%) | C6: Planned percentage of the population with electricity access by 2030.
B7: Target Urban Electricity Access Rate by 2030 (%) | C7: Planned percentage of the urban population with electricity access by 2030.
B8: Target Rural Electricity Access Rate by 2030 (%) | C8: Planned percentage of the rural population with electricity access by 2030.
B9: Population Without Electricity (people) | C9: Number of people without access to electricity when explicitly stated.
B10: Installed Capacity – Current (MW) | C10: Total installed electricity generation capacity at time of reporting.
B11: Installed Capacity – 2030 Target (MW) | C11: Planned total installed generation capacity by 2030.
B12: New Generation Required (MW) | C12: Additional generation capacity explicitly stated as required.
B13: Renewable Capacity – Current (MW) | C13: Installed renewable electricity generation capacity.
... B43: Universal Access Target Year | C43: Year universal electricity access is targeted.

Sheet Complete_Data_Quantitative
A1: Category | B1: Indicator | C1: Data Source | D1: Comments | E1: Benin | F1: Botswana | G1: Burundi | H1: Cameroon | I1: Chad | J1: Comoros | K1: Ivory Coast | L1: Democratic Republic of Congo | M1: Ethiopia | N1: Gambia | O1: Ghana | P1: Guinea | Q1: Kenya | R1: Lesotho | S1: Liberia | T1: Madagascar | U1: Malawi | V1: Mauritania | W1: Mozambique | X1: Namibia | Y1: Niger | Z1: Nigeria | AA1: Republic of Congo | AB1: São Tomé and Príncipe | AC1: Senegal | AD1: Sierra Leone | AE1: Tanzania | AF1: Togo | AG1: Zambia | AH1: Zimbabwe
A2: Electricity Access | B2: Current Electricity Access Rate (%) | C2: M300 National Energy Compacts | D2: Percentage of the total population that currently has access to electricity through grid or off-grid solutions. | E2: 42.6 | F2: 76.6 | G2: 25.9 | H2: 74 | I2: 11 | J2: 95 | K2: 64 | L2: 21.5 | M2: 44 | N2: 73.7 | O2: 89 | P2: 53 | Q2: 75 | R2: 53 | S2: 32.7 | T2: 36 | U2: 25.9 | V2: 55 | W2: 60.1 | X2: 59.5 | Y2: 20.84 | Z2: 61 | AA2: 31.66 | AB2: 84 | AC2: 84 | AD2: 36 | AE2: 78.4 | AF2: 70 | AG2: 53.6 | AH2: 62
B3: Current Urban Electricity Access Rate (%) | C3: M300 National Energy Compacts | D3: Share of the urban population with access to electricity. | E3: 71.2 | F3: 90 | G3: 66.3 | H3: 94 | I3: 20 | J3: 80 | L3: 60.8 | N3: 97 | P3: 89 | R3: 71.3 | S3: 50 | T3: 72 | U3: 56.5 | V3: 91 | X3: 77.1 | AA3: 38.67 | AC3: 97.1 | AE3: 99.6 | AG3: 80.3 | AH3: 83
B4: Current Rural Electricity Access Rate (%) | C4: M300 National Energy Compacts | D4: Share of the rural population with access to electricity. | E4: 13.1 | G4: 17.6 | H4: 25 | I4: 1 | J4: 20 | L4: 5 | M4: 57 | N4: 45 | P4: 21 | R4: 11.4 | S4: 10 | T4: 11 | U4: 3.8 | V4: 6 | X4: 13.8 | Y4: 5.3 | AA4: 1.01 | AC4: 64.5 | AE4: 69.6 | AG4: 34.9 | AH4: 27
B5: Target Electricity Access Rate by 2030 (%) | C5: M300 National Energy Compacts | D5: Percentage of the population targeted to have electricity access by 2030. | E5: 70 | F5: 100 | G5: 70 | H5: 100 | I5: 90 | J5: 100 | K5: 100 | L5: 62 | M5: 75 | N5: 100 | O5: 99.8 | P5: 100 | Q5: 100 | R5: 100 | S5: 75 | T5: 80 | U5: 70 | V5: 100 | W5: 100 | X5: 70 | Y5: 60 | Z5: 100 | AA5: 81.3 | AB5: 100 | AC5: 100 | AD5: 78 | AE5: 100 | AF5: 100 | AG5: 100 | AH5: 100
B6: Target Urban Electricity Access Rate by 2030 (%) | C6: M300 National Energy Compacts | D6: Electricity access rate targeted for urban areas by 2030. | I6: 50 | U6: 59.5 | V6: 98 | AA6: 90
B7: Target Rural Electricity Access Rate by 2030 (%) | C7: M300 National Energy Compacts | D7: Electricity access rate targeted for rural areas by 2030. | I7: 40 | U7: 24.1 | V7: 80 | AA7: 50 | AG7: 51
B8: Population Without Electricity (people) | C8: M300 National Energy Compacts | D8: Number of people currently living without electricity access. | G8: 11600000 | H8: 33000000 | I8: 14000000 | J8: 226615 | L8: 60000000 | N8: 633000 | O8: 3700000 | P8: 7750000 | T8: 19000000 | V8: 3400000 | Z8: 86000000 | AC8: 2800000
A9: Generation Capacity & Supply Mix | B9: Installed Capacity – Current (MW) | C9: M300 National Energy Compacts | D9: Total electricity generation capacity currently installed and operational. | E9: 199.8 | F9: 892 | G9: 204.88 | H9: 3000 | I9: 487 | J9: 53 | K9: 2907 | L9: 3067 | M9: 9761 | N9: 99 | O9: 5641 | P9: 1310 | Q9: 2627 | R9: 104.7 | S9: 126 | T9: 828 | U9: 550 | V9: 615.1 | W9: 2922 | X9: 695 | Y9: 352 | Z9: 12000 | AA9: 748 | AB9: 38 | AD9: 271 | AE9: 3404.2 | AF9: 267.5 | AG9: 3811.3 | AH9: 2962
B10: Installed Capacity – 2030 Target (MW) | C10: M300 National Energy Compacts | D10: Total generation capacity planned to be installed by 2030. | E10: 794 | F10: 950 | G10: 410 | H10: 3000 | I10: 866 | K10: 5128 | L10: 13576 | M10: 14000 | O10: 6200 | P10: 3827 | Q10: 5952 | U10: 1490 | X10: 1149 | AA10: 3701 | AD10: 1120 | AF10: 1154.5 | AG10: 10000 | AH10: 5432
B11: New Generation Required (MW) | C11: M300 National Energy Compacts | D11: Additional generation capacity required to meet future demand and access targets. | I11: 866 | K11: 1374 | P11: 2517 | Q11: 3325 | U11: 848 | W11: 3100 | X11: 454 | AA11: 2953 | AB11: 60 | AE11: 1973 | AF11: 894 | AG11: 6200
B12: Renewable Capacity – Current (MW) | C12: M300 National Energy Compacts | D12: Installed electricity generation capacity from renewable energy sources. | E12: 62.3 | F12: 74.6 | H12: 36.53 | J12: 13.71 | K12: 909 | N12: 23 | O12: 60.8 | P12: 817 | R12: 104.3 | S12: 88 | T12: 240 | U12: 499 | W12: 2291 | X12: 498.5 | AA12: 214 | AC12: 460 | AE12: 2011.27 | AF12: 102.5 | AG12: 3336 | AH12: 1282
B13: Renewable Capacity – 2030 Target (MW) | C13: M300 National Energy Compacts | D13: Renewable energy generation capacity targeted by 2030. | E13: 417 | F13: 475 | I13: 520 | K13: 2283 | P13: 2689 | S13: 238 | T13: 893 | W13: 4892 | X13: 952.5 | AA13: 2697 | AF13: 728.5 | AG13: 9000 | AH13: 2640
B14: Solar Capacity Target (MW) | C14: M300 National Energy Compacts | D14: Planned installed solar power capacity by 2030. | F14: 1500 | G14: 254 | H14: 150 | I14: 520 | K14: 399 | L14: 4000 | M14: 1175 | N14: 150 | O14: 850 | P14: 1086 | Q14: 807 | R14: 164 | S14: 172 | T14: 560 | V14: 50 | W14: 303 | X14: 466.5 | AD14: 392 | AE14: 463 | AF14: 569 | AG14: 3000 | AH14: 1500
B15: Wind Capacity Target (MW) | C15: M300 National Energy Compacts | D15: Planned installed wind power capacity by 2030. | F15: 100 | M15: 1102 | O15: 200 | Q15: 966 | R15: 60 | T15: 16 | V15: 30 | W15: 245 | X15: 99 | Y15: 250 | AE15: 500 | AG15: 1192
B16: Hydro Capacity Target (MW) | C16: M300 National Energy Compacts | D16: Planned installed hydropower capacity by 2030. | G16: 155.5 | H16: 600 | I16: 120 | J16: 1.95 | K16: 829 | M16: 1800 | O16: 150 | P16: 791 | Q16: 1403 | R16: 1.1 | S16: 150 | T16: 374 | W16: 4344 | X16: 347 | Y16: 128 | AB16: 9 | AD16: 194 | AE16: 880 | AF16: 57
B17: Gas Capacity Target (MW) | C17: M300 National Energy Compacts | D17: Planned installed gas-fired generation capacity by 2030. | N17: 80 | V17: 225 | W17: 1004 | Y17: 240 | AA17: 470 | AB17: 10 | AC17: 2200 | AF17: 250
B18: Battery Storage Target (MWh) | C18: M300 National Energy Compacts | D18: Planned electricity storage capacity to support grid stability and renewable integration. | F18: 140 | I18: 60 | J18: 19.6 | N18: 40 | Q18: 400 | R18: 600 | S18: 5 | V18: 30 | X18: 96 | Y18: 20 | AF18: 156
A19: Demand | B19: Peak Demand – Current (MW) | C19: M300 National Energy Compacts | D19: Highest electricity demand currently observed on the power system. | F19: 678 | J19: 26.2 | R19: 209 | S19: 108 | X19: 673 | AD19: 320 | AE19: 1888.72 | AG19: 2500 | AH19: 2000
B20: Peak Demand – 2030 (MW) | C20: M300 National Energy Compacts | D20: Projected maximum electricity demand expected by 2030. | P20: 3894 | U20: 774 | AD20: 485
A21: Networks & Losses | B21: Transmission Lines – Existing (km) | C21: M300 National Energy Compacts | D21: Total length of existing high-voltage transmission lines. | E21: 1449.1 | F21: 4000 | G21: 650 | I21: 996 | K21: 7553 | M21: 20390 | N21: 18 | O21: 6472.2 | P21: 1600 | Q21: 9484 | S21: 1398 | U21: 2650 | V21: 1950 | W21: 5679 | Y21: 1428.8 | Z21: 12330 | AA21: 1756 | AB21: 275 | AD21: 802 | AE21: 8025.75 | AF21: 1273 | AG21: 12705
B22: Transmission Lines – Added (km) | C22: M300 National Energy Compacts | D22: Additional transmission lines planned for construction. | G22: 704 | I22: 400.2 | K22: 10212 | N22: 200 | P22: 352 | Q22: 8000 | U22: 1940 | V22: 2550 | W22: 2000 | AD22: 1235 | AF22: 1447 | AG22: 17913 | AH22: 1607
B23: Distribution Lines – Added (km) | C23: M300 National Energy Compacts | D23: Additional electricity distribution network lines planned. | G23: 6578 | I23: 195 | K23: 93848 | Q23: 212937 | R23: 550 | U23: 22417 | V23: 4550 | AC23: 39000 | AF23: 3761
B24: System Losses – Current (%) | C24: M300 National Energy Compacts | D24: Percentage of electricity lost through technical and non-technical losses. | E24: 24.62 | F24: 14.35 | I24: 39 | J24: 37 | L24: 46 | M24: 27 | N24: 21 | O24: 27 | P24: 30 | Q24: 15.69 | S24: 45.4 | T24: 30 | V24: 30 | W24: 24 | Z24: 42 | AA24: 45 | AB24: 34 | AD24: 50 | AE24: 14.2 | AF24: 16
B25: Efficiency - System Losses (%) | C25: World Bank UPBEAT Database | D25: Power system efficiency expressed as the inverse of system losses. | E25: 24 | F25: 15.35 | G25: 19.22 | I25: 37 | K25: 14.98 | L25: 31.2 | N25: 17.6 | P25: 19 | Q25: 23 | R25: 12.87 | S25: 32 | T25: 27.38 | U25: 20.99 | V25: 22.92 | W25: 26 | Y25: 23.55 | AB25: 24.3 | AC25: 17.7 | AE25: 14.49 | AF25: 16.04 | AH25: 17.5
B26: System Losses – Target (%) | C26: M300 National Energy Compacts | D26: Targeted reduction level of system losses by 2030. | E26: 15 | H26: 10 | I26: 15 | J26: 20 | L26: 15 | M26: 19 | N26: 18 | O26: 23 | P26: 8 | Q26: 12.8 | T26: 16 | V26: 20 | AB26: 18 | AF26: 12
A27: Connections | B27: Grid Connections – New (connections) | C27: M300 National Energy Compacts | D27: Number of new electricity connections planned through the national grid. | E27: 928000 | F27: 220000 | G27: 1900000 | H27: 8000000 | I27: 17500000 | J27: 62310 | K27: 3070000 | L27: 60000000 | M27: 6461000 | N27: 20000 | O27: 660000 | P27: 7750000 | Q27: 5100000 | R27: 26400 | S27: 100000 | T27: 3500000 | U27: 1150000 | V27: 3389524 | W27: 4900000 | X27: 175000 | Y27: 2077515 | Z27: 4700000 | AA27: 953000 | AB27: 8000 | AC27: 260149 | AD27: 160000 | AE27: 8300000 | AF27: 1300000 | AG27: 1459560 | AH27: 1200000
B28: Grid Connections – New (HH) | C28: M300 National Energy Compacts | D28: Number of households planned to be newly connected to the grid. | O28: 660000 | X28: 175000 | AD28: 160000 | AE28: 8300000
B29: Off-grid Connections Target (connections) | C29: M300 National Energy Compacts | D29: Total number of electricity connections planned through off-grid solutions. | F29: 61000 | G29: 410000 | I29: 20000 | J29: 3739 | K29: 5800000 | R29: 18900 | S29: 40000 | U29: 1550000 | V29: 1054204 | W29: 435000 | X29: 35000 | Y29: 115301 | Z29: 93193 | AB29: 800 | AD29: 560000 | AF29: 133000 | AG29: 1768311 | AH29: 1500000
B30: Off-grid Connections Target (Mini-grids) | C30: M300 National Energy Compacts | D30: Number of off-grid connections provided via mini-grids. | M30: 2769000 | T30: 200 | Y30: 115301 | AC30: 1600000
B31: Off-grid Connections Target (Solar kits) | C31: M300 National Energy Compacts | D31: Number of off-grid connections provided via solar home systems. | V31: 435249 | Y31: 690392 | Z31: 2930000 | AC31: 1200000 | AJ31: =ISBLANK -> #NAME?
B32: Off-grid Connections Target (HH) | C32: M300 National Energy Compacts | D32: Number of households expected to gain off-grid electricity access. | X32: 35000 | AB32: 800 | AD32: 560000
B33: Mini-grid Sites Target (count) | C33: M300 National Energy Compacts | D33: Number of mini-grid installations planned. | F33: 6 | G33: 300 | O33: 400 | P33: 714 | Q33: 199048 | R33: 11 | U33: 3 | V33: 120 | W33: 98 | Y33: 115301 | Z33: 158 | AC33: 150 | AD33: 100 | AE33: 68
B34: Mini-grid Capacity Target (MW) | C34: M300 National Energy Compacts | D34: Total electricity generation capacity of planned mini-grids. | G34: 300 | O34: 0.24 | W34: 11.6 | AC34: 50 | AD34: 40
B35: SHS Connections Target (connections) | C35: M300 National Energy Compacts | D35: Number of Solar Home System connections targeted. | G35: 850000 | I35: 30000 | O35: 1000000 | P35: 1326 | S35: 49441 | U35: 244000 | W35: 175235 | Y35: 690392 | AB35: 800 | AC35: 300000 | AD35: 400000 | AF35: 133000
A36: Finance | B36: Total Investment Required (USD) | C36: M300 National Energy Compacts | D36: Total estimated investment required to achieve electricity and clean cooking targets. | E36: 2360000000 | F36: 2520000000 | G36: 3490000000 | H36: 12554000000 | I36: 1950000000 | J36: 390210000 | K36: 6560000000 | L36: 37048660000 | M36: 9646040000 | N36: 552000000 | O36: 4404000000 | P36: 8900000000 | Q36: 18730000000 | R36: 1970000000 | S36: 1250000000 | T36: 7200000000 | U36: 5500000000 | V36: 2450000000 | W36: 18620000000 | X36: 1764000000 | Z36: 32700000000 | AA36: 11543000000 | AB36: 297000000 | AC36: 6300000000 | AD36: 2245000000 | AE36: 12889999999 | AF36: 3000000000 | AG36: 11880000000 | AH36: 9134890000
B37: Public Financing Required (USD) | C37: M300 National Energy Compacts | D37: Portion of total investment expected from public funding sources. | E37: 1420000000 | F37: 1414000000 | G37: 1950000000 | I37: 1299744000 | J37: 117000000 | K37: 4620000000 | L37: 17314100000 | M37: 6584240000 | N37: 305000000 | O37: 1793000000 | P37: 1200000000 | Q37: 10820000000 | R37: 499700000 | T37: 2880000000 | W37: 9923000000 | X37: 1353000000 | Z37: 17200000000 | AA37: 3276000000 | AB37: 108000000 | AD37: 835000000 | AE37: 8850000000 | AF37: 1320000000
B38: Private Financing Required (USD) | C38: M300 National Energy Compacts | D38: Portion of total investment expected from private sector financing. | E38: 940000000 | F38: 1106000000 | G38: 1540000000 | H38: 6372000000 | I38: 650256000 | J38: 273000000 | K38: 1940000000 | L38: 19734550000 | M38: 3061800000 | N38: 247000000 | O38: 2611000000 | P38: 7641000000 | Q38: 7910000000 | R38: 1470000000 | S38: 150000000 | T38: 4320000000 | U38: 162800000 | V38: 1230000000 | W38: 8698000000 | X38: 411000000 | Y38: 527000000 | Z38: 15500000000 | AA38: 8267000000 | AB38: 190000000 | AC38: 2300000000 | AD38: 1410000000 | AE38: 4039000000 | AF38: 1680000000 | AG38: 9500000000 | AH38: 4420000000
B39: World Bank Financing (USD) | C39: M300 National Energy Compacts | D39: Expected financing contribution from the World Bank. | O39: 260000000 | R39: 52900000 | S39: 200000000
B40: AfDB Financing (USD) | C40: M300 National Energy Compacts | D40: Expected financing contribution from the African Development Bank. | O40: 85000000 | R40: 10600000
...

Sheet Sheet1
F1: Indicator | G1: Definition / Explanation
E2: Current Electricity Access Rate (%) | F2: Current Electricity Access Rate (%) | G2: Percentage of the total population that currently has access to electricity through grid or off-grid solutions.
E3: Current Urban Electricity Access Rate (%) | F3: Current Urban Electricity Access Rate (%) | G3: Share of the urban population with access to electricity.
E4: Current Rural Electricity Access Rate (%) | F4: Current Rural Electricity Access Rate (%) | G4: Share of the rural population with access to electricity.
E5: Target Electricity Access Rate by 2030 (%) | F5: Target Electricity Access Rate by 2030 (%) | G5: Percentage of the population targeted to have electricity access by 2030.
E6: Target Urban Electricity Access Rate by 2030 (%) | F6: Target Urban Electricity Access Rate by 2030 (%) | G6: Electricity access rate targeted for urban areas by 2030.
E7: Target Rural Electricity Access Rate by 2030 (%) | F7: Target Rural Electricity Access Rate by 2030 (%) | G7: Electricity access rate targeted for rural areas by 2030.
E8: Population Without Electricity (people) | F8: Population Without Electricity (people) | G8: Number of people currently living without electricity access.
E9: Installed Capacity – Current (MW) | F9: Installed Capacity – Current (MW) | G9: Total electricity generation capacity currently installed and operational.
E10: Installed Capacity – 2030 Target (MW) | F10: Installed Capacity – 2030 Target (MW) | G10: Total generation capacity planned to be installed by 2030.
E11: New Generation Required (MW) | F11: New Generation Required (MW) | G11: Additional generation capacity required to meet future demand and access targets.
E12: Renewable Capacity – Current (MW) | F12: Renewable Capacity – Current (MW) | G12: Installed electricity generation capacity from renewable energy sources.
E13: Renewable Capacity – 2030 Target (MW) | F13: Renewable Capacity – 2030 Target (MW) | G13: Renewable energy generation capacity targeted by 2030.
... E78: 2030 Projected population (million) | F78: 2030 Projected Population (million) | G78: Projected total population in 2030 based on demographic forecasts.

Sheet Derived_Data_Quantitative
A1: Category | B1: Indicator | C1: Benin | D1: Botswana | E1: Burundi | F1: Cameroon | G1: Chad | H1: Comoros | I1: Côte d’Ivoire | J1: DRC | K1: Ethiopia | L1: Gambia | M1: Ghana | N1: Guinea | O1: Kenya | P1: Lesotho | Q1: Liberia | R1: Madagascar | S1: Malawi | T1: Mauritania | U1: Mozambique | V1: Namibia | W1: Niger | X1: Nigeria | Y1: Republic of Congo | Z1: São Tomé & Príncipe | AA1: Senegal | AB1: Sierra Leone | AC1: Togo | AD1: Tanzania | AE1: Zambia | AF1: Zimbabwe
A2: Electricity Access | B2: Current electricity access gap (million) | C2: =Raw_Data_Quantitative!D66*(1-Raw_Data_Quantitative!D2/100) -> 8.323 | D2: =Raw_Data_Quantitative!E66*(1-Raw_Data_Quantitative!E2/100) -> 0.585 | E2: =Raw_Data_Quantitative!F66*(1-Raw_Data_Quantitative!F2/100) -> 10.374 | F2: =Raw_Data_Quantitative!G66*(1-Raw_Data_Quantitative!G2/100) -> 7.566 | G2: =Raw_Data_Quantitative!H66*(1-Raw_Data_Quantitative!H2/100) -> 18.067 | H2: =Raw_Data_Quantitative!I66*(1-Raw_Data_Quantitative!I2/100) -> 0.9 | I2: =Raw_Data_Quantitative!J66*(1-Raw_Data_Quantitative!J2/100) -> 11.484 | J2: =Raw_Data_Quantitative!K66*(1-Raw_Data_Quantitative!K2/100) -> 85.8005 | ... AF2: =Raw_Data_Quantitative!AG66*(1-Raw_Data_Quantitative!AG2/100) -> 6.308 | AG2: =SUM(C2:AF2) -> 460.20822
B3: 2030 electricity access gap (million) | C3: =IF(Raw_Data_Quantitative!D5 = 0, C2, Raw_Data_Quantitative!D67*(1-Raw_Data_Quantitative!D5/100)) -> 4.9856466 | D3: =IF(Raw_Data_Quantitative!E5 = 0, D2, Raw_Data_Quantitative!E67*(1-Raw_Data_Quantitative!E5/100)) -> 0 | E3: =IF(Raw_Data_Quantitative!F5 = 0, E2, Raw_Data_Quantitative!F67*(1-Raw_Data_Quantitative!F5/100)) -> 4.854605 | F3: =IF(Raw_Data_Quantitative!G5 = 0, F2, Raw_Data_Quantitative!G67*(1-Raw_Data_Quantitative!G5/100)) -> 0 | G3: =IF(Raw_Data_Quantitative!H5 = 0, G2, Raw_Data_Quantitative!H67*(1-Raw_Data_Quantitative!H5/100)) -> 2.4207479 | H3: =IF(Raw_Data_Quantitative!I5 = 0, H2, Raw_Data_Quantitative!I67*(1-Raw_Data_Quantitative!I5/100)) -> 0 | I3: =IF(Raw_Data_Quantitative!J5 = 0, I2, Raw_Data_Quantitative!J67*(1-Raw_Data_Quantitative!J5/100)) -> 0 | J3: =IF(Raw_Data_Quantitative!K5 = 0, J2, Raw_Data_Quantitative!K67*(1-Raw_Data_Quantitative!K5/100)) -> 49.982236 | ... AF3: =IF(Raw_Data_Quantitative!AG5 = 0, AF2, Raw_Data_Quantitative!AG67*(1-Raw_Data_Quantitative!AG5/100)) -> 0 | AG3: =SUM(C3:AF3) -> 134.53068
B4: Electricity access gap reduction, 2024-2030 (million) | C4: =C2-C3 -> 3.3373534 | D4: =D2-D3 -> 0.585 | E4: =E2-E3 -> 5.519395 | F4: =F2-F3 -> 7.566 | G4: =G2-G3 -> 15.646252 | H4: =H2-H3 -> 0.9 | I4: =I2-I3 -> 11.484 | J4: =J2-J3 -> 35.818264 | ... AF4: =AF2-AF3 -> 6.308 | AG4: =SUM(C4:AF4) -> 325.67754
B5: Electricity access population increase, 2024-2030 (million) | C5: =(Raw_Data_Quantitative!D67*(Raw_Data_Quantitative!D5/100))-(Raw_Data_Quantitative!D66*(Raw_Data_Quantitative!D2/100)) -> 5.4561754 | D5: =(Raw_Data_Quantitative!E67*(Raw_Data_Quantitative!E5/100))-(Raw_Data_Quantitative!E66*(Raw_Data_Quantitative!E2/100)) -> 0.8509175 | E5: =(Raw_Data_Quantitative!F67*(Raw_Data_Quantitative!F5/100))-(Raw_Data_Quantitative!F66*(Raw_Data_Quantitative!F2/100)) -> 7.7014115 | F5: =(Raw_Data_Quantitative!G67*(Raw_Data_Quantitative!G5/100))-(Raw_Data_Quantitative!G66*(Raw_Data_Quantitative!G2/100)) -> 12.243189 | G5: =(Raw_Data_Quantitative!H67*(Raw_Data_Quantitative!H5/100))-(Raw_Data_Quantitative!H66*(Raw_Data_Quantitative!H2/100)) -> 19.553731 | H5: =(Raw_Data_Quantitative!I67*(Raw_Data_Quantitative!I5/100))-(Raw_Data_Quantitative!I66*(Raw_Data_Quantitative!I2/100)) -> 0.9642645 | I5: =(Raw_Data_Quantitative!J67*(Raw_Data_Quantitative!J5/100))-(Raw_Data_Quantitative!J66*(Raw_Data_Quantitative!J2/100)) -> 16.283009 | J5: =(Raw_Data_Quantitative!K67*(Raw_Data_Quantitative!K5/100))-(Raw_Data_Quantitative!K66*(Raw_Data_Quantitative!K2/100)) -> 58.050465 | ... AF5: =(Raw_Data_Quantitative!AG67*(Raw_Data_Quantitative!AG5/100))-(Raw_Data_Quantitative!AG66*(Raw_Data_Quantitative!AG2/100)) -> 8.3183485 | AG5: =SUM(C5:AF5) -> 475.49952
A6: Clean Cooking Access | B6: Current clean cooking access gap (million) | C6: =Raw_Data_Quantitative!D66*(1-Raw_Data_Quantitative!D50/100) -> 12.9775 | D6: =Raw_Data_Quantitative!E66*(1-Raw_Data_Quantitative!E50/100) -> 0.835 | E6: =Raw_Data_Quantitative!F66*(1-Raw_Data_Quantitative!F50/100) -> 14 | F6: =Raw_Data_Quantitative!G66*(1-Raw_Data_Quantitative!G50/100) -> 22.2906 | G6: =Raw_Data_Quantitative!H66*(1-Raw_Data_Quantitative!H50/100) -> 20.3 | H6: =Raw_Data_Quantitative!I66*(1-Raw_Data_Quantitative!I50/100) -> 0.8955 | I6: =Raw_Data_Quantitative!J66*(1-Raw_Data_Quantitative!J50/100) -> 25.52 | J6: =Raw_Data_Quantitative!K66*(1-Raw_Data_Quantitative!K50/100) -> 103.835 | ... AF6: =Raw_Data_Quantitative!AG66*(1-Raw_Data_Quantitative!AG50/100) -> 10.1924 | AG6: =SUM(C6:AF6) -> 809.452
B7: 2030 clean cooking access gap (million) | C7: =IF(Raw_Data_Quantitative!D58=0,C6,Raw_Data_Quantitative!D67*(1-Raw_Data_Quantitative!D58/100)) -> 8.309411 | D7: =IF(Raw_Data_Quantitative!E58=0,D6,Raw_Data_Quantitative!E67*(1-Raw_Data_Quantitative!E58/100)) -> 0.27659175 | E7: =IF(Raw_Data_Quantitative!F58=0,E6,Raw_Data_Quantitative!F67*(1-Raw_Data_Quantitative!F58/100)) -> 9.7092099 | F7: =IF(Raw_Data_Quantitative!G58=0,F6,Raw_Data_Quantitative!G67*(1-Raw_Data_Quantitative!G58/100)) -> 20.266314 | G7: =IF(Raw_Data_Quantitative!H58=0,G6,Raw_Data_Quantitative!H67*(1-Raw_Data_Quantitative!H58/100)) -> 13.072039 | H7: =IF(Raw_Data_Quantitative!I58=0,H6,Raw_Data_Quantitative!I67*(1-Raw_Data_Quantitative!I58/100)) -> 0.67498515 | I7: =IF(Raw_Data_Quantitative!J58=0,I6,Raw_Data_Quantitative!J67*(1-Raw_Data_Quantitative!J58/100)) -> 18.349504 | J7: =IF(Raw_Data_Quantitative!K58=0,J6,Raw_Data_Quantitative!K67*(1-Raw_Data_Quantitative!K58/100)) -> 92.072541 | ... AF7: =IF(Raw_Data_Quantitative!AG58=0,AF6,Raw_Data_Quantitative!AG67*(1-Raw_Data_Quantitative!AG58/100)) -> 5.5831046 | AG7: =SUM(C7:AF7) -> 411.04683
B8: Clean cooking access gap reduction, 2024-2030 (million) | C8: =C6-C7 -> 4.668089 | D8: =D6-D7 -> 0.55840825 | E8: =E6-E7 -> 4.2907901 | F8: =F6-F7 -> 2.0242863 | G8: =G6-G7 -> 7.2279613 | H8: =H6-H7 -> 0.22051485 | I8: =I6-I7 -> 7.1704955 | J8: =J6-J7 -> 11.762459 | ... AF8: =AF6-AF7 -> 4.6092955 | AG8: =SUM(C8:AF8) -> 398.40517
B9: Clean cooking population increase, 2024-2030 (million) | C9: =(Raw_Data_Quantitative!D67*(Raw_Data_Quantitative!D58/100))-(Raw_Data_Quantitative!D66*(Raw_Data_Quantitative!D50/100)) -> 6.786911 | D9: =(Raw_Data_Quantitative!E67*(Raw_Data_Quantitative!E58/100))-(Raw_Data_Quantitative!E66*(Raw_Data_Quantitative!E50/100)) -> 0.82432575 | E9: =(Raw_Data_Quantitative!F67*(Raw_Data_Quantitative!F58/100))-(Raw_Data_Quantitative!F66*(Raw_Data_Quantitative!F50/100)) -> 6.4728066 | F9: =(Raw_Data_Quantitative!G67*(Raw_Data_Quantitative!G58/100))-(Raw_Data_Quantitative!G66*(Raw_Data_Quantitative!G50/100)) -> 6.7014758 | G9: =(Raw_Data_Quantitative!H67*(Raw_Data_Quantitative!H58/100))-(Raw_Data_Quantitative!H66*(Raw_Data_Quantitative!H50/100)) -> 11.13544 | H9: =(Raw_Data_Quantitative!I67*(Raw_Data_Quantitative!I58/100))-(Raw_Data_Quantitative!I66*(Raw_Data_Quantitative!I50/100)) -> 0.28477935 | I9: =(Raw_Data_Quantitative!J67*(Raw_Data_Quantitative!J58/100))-(Raw_Data_Quantitative!J66*(Raw_Data_Quantitative!J50/100)) -> 11.969504 | J9: =(Raw_Data_Quantitative!K67*(Raw_Data_Quantitative!K58/100))-(Raw_Data_Quantitative!K66*(Raw_Data_Quantitative!K50/100)) -> 33.99466 | ... AF9: =(Raw_Data_Quantitative!AG67*(Raw_Data_Quantitative!AG58/100))-(Raw_Data_Quantitative!AG66*(Raw_Data_Quantitative!AG50/100)) -> 6.6196439 | AG9: =SUM(C9:AF9) -> 541.08234
B10: USD per Unserved Person
B11: MW per Million People
B12: Investment per MW Installed (USD/MW)
B13: Access Gap (% to Universal)
B14: Renewable Share Increase (% points)

Sheet Copy of Derived_Data_Quantitati
A1: Category | B1: Indicator | D1: Benin | E1: Botswana | F1: Burundi | G1: Cameroon | H1: Chad | I1: Comoros | J1: Côte d’Ivoire | K1: DRC | L1: Ethiopia | M1: Gambia | N1: Ghana | O1: Guinea | P1: Kenya | Q1: Lesotho | R1: Liberia | S1: Madagascar | T1: Malawi | U1: Mauritania | V1: Mozambique | W1: Namibia | X1: Niger | Y1: Nigeria | Z1: Republic of Congo | AA1: São Tomé & Príncipe | AB1: Senegal | AC1: Sierra Leone | AD1: Togo | AE1: Tanzania | AF1: Zambia | AG1: Zimbabwe
A2: Electricity Access | B2: Current electricity access gap (million) | D2: =Raw_Data_Quantitative!D66*(1-Raw_Data_Quantitative!D2/100) -> 8.323 | E2: =Raw_Data_Quantitative!E66*(1-Raw_Data_Quantitative!E2/100) -> 0.585 | F2: =Raw_Data_Quantitative!F66*(1-Raw_Data_Quantitative!F2/100) -> 10.374 | G2: =Raw_Data_Quantitative!G66*(1-Raw_Data_Quantitative!G2/100) -> 7.566 | H2: =Raw_Data_Quantitative!H66*(1-Raw_Data_Quantitative!H2/100) -> 18.067 | I2: =Raw_Data_Quantitative!I66*(1-Raw_Data_Quantitative!I2/100) -> 0.9 | J2: =Raw_Data_Quantitative!J66*(1-Raw_Data_Quantitative!J2/100) -> 11.484 | K2: =Raw_Data_Quantitative!K66*(1-Raw_Data_Quantitative!K2/100) -> 85.8005 | ... AG2: =Raw_Data_Quantitative!AG66*(1-Raw_Data_Quantitative!AG2/100) -> 6.308 | AH2: =SUM(D2:AG2) -> 460.20822
B3: 2030 electricity access gap (million) | D3: =IF(Raw_Data_Quantitative!D5 = 0, D2, Raw_Data_Quantitative!D67*(1-Raw_Data_Quantitative!D5/100)) -> 4.9856466 | E3: =IF(Raw_Data_Quantitative!E5 = 0, E2, Raw_Data_Quantitative!E67*(1-Raw_Data_Quantitative!E5/100)) -> 0 | F3: =IF(Raw_Data_Quantitative!F5 = 0, F2, Raw_Data_Quantitative!F67*(1-Raw_Data_Quantitative!F5/100)) -> 4.854605 | G3: =IF(Raw_Data_Quantitative!G5 = 0, G2, Raw_Data_Quantitative!G67*(1-Raw_Data_Quantitative!G5/100)) -> 0 | H3: =IF(Raw_Data_Quantitative!H5 = 0, H2, Raw_Data_Quantitative!H67*(1-Raw_Data_Quantitative!H5/100)) -> 2.4207479 | I3: =IF(Raw_Data_Quantitative!I5 = 0, I2, Raw_Data_Quantitative!I67*(1-Raw_Data_Quantitative!I5/100)) -> 0 | J3: =IF(Raw_Data_Quantitative!J5 = 0, J2, Raw_Data_Quantitative!J67*(1-Raw_Data_Quantitative!J5/100)) -> 0 | K3: =IF(Raw_Data_Quantitative!K5 = 0, K2, Raw_Data_Quantitative!K67*(1-Raw_Data_Quantitative!K5/100)) -> 49.982236 | ... AG3: =IF(Raw_Data_Quantitative!AG5 = 0, AG2, Raw_Data_Quantitative!AG67*(1-Raw_Data_Quantitative!AG5/100)) -> 0 | AH3: =SUM(D3:AG3) -> 134.53068
B4: Electricity access gap reduction, 2024-2030 (million) | D4: =D2-D3 -> 3.3373534 | E4: =E2-E3 -> 0.585 | F4: =F2-F3 -> 5.519395 | G4: =G2-G3 -> 7.566 | H4: =H2-H3 -> 15.646252 | I4: =I2-I3 -> 0.9 | J4: =J2-J3 -> 11.484 | K4: =K2-K3 -> 35.818264 | ... AG4: =AG2-AG3 -> 6.308 | AH4: =SUM(D4:AG4) -> 325.67754
B5: Electricity access population increase, 2024-2030 (million) | D5: =(Raw_Data_Quantitative!D67*(Raw_Data_Quantitative!D5/100))-(Raw_Data_Quantitative!D66*(Raw_Data_Quantitative!D2/100)) -> 5.4561754 | E5: =(Raw_Data_Quantitative!E67*(Raw_Data_Quantitative!E5/100))-(Raw_Data_Quantitative!E66*(Raw_Data_Quantitative!E2/100)) -> 0.8509175 | F5: =(Raw_Data_Quantitative!F67*(Raw_Data_Quantitative!F5/100))-(Raw_Data_Quantitative!F66*(Raw_Data_Quantitative!F2/100)) -> 7.7014115 | G5: =(Raw_Data_Quantitative!G67*(Raw_Data_Quantitative!G5/100))-(Raw_Data_Quantitative!G66*(Raw_Data_Quantitative!G2/100)) -> 12.243189 | H5: =(Raw_Data_Quantitative!H67*(Raw_Data_Quantitative!H5/100))-(Raw_Data_Quantitative!H66*(Raw_Data_Quantitative!H2/100)) -> 19.553731 | I5: =(Raw_Data_Quantitative!I67*(Raw_Data_Quantitative!I5/100))-(Raw_Data_Quantitative!I66*(Raw_Data_Quantitative!I2/100)) -> 0.9642645 | J5: =(Raw_Data_Quantitative!J67*(Raw_Data_Quantitative!J5/100))-(Raw_Data_Quantitative!J66*(Raw_Data_Quantitative!J2/100)) -> 16.283009 | K5: =(Raw_Data_Quantitative!K67*(Raw_Data_Quantitative!K5/100))-(Raw_Data_Quantitative!K66*(Raw_Data_Quantitative!K2/100)) -> 58.050465 | ... AG5: =(Raw_Data_Quantitative!AG67*(Raw_Data_Quantitative!AG5/100))-(Raw_Data_Quantitative!AG66*(Raw_Data_Quantitative!AG2/100)) -> 8.3183485 | AH5: =SUM(D5:AG5) -> 475.49952
A6: Clean Cooking Access | B6: Current clean cooking access gap (million) | D6: =Raw_Data_Quantitative!D66*(1-Raw_Data_Quantitative!D50/100) -> 12.9775 | E6: =Raw_Data_Quantitative!E66*(1-Raw_Data_Quantitative!E50/100) -> 0.835 | F6: =Raw_Data_Quantitative!F66*(1-Raw_Data_Quantitative!F50/100) -> 14 | G6: =Raw_Data_Quantitative!G66*(1-Raw_Data_Quantitative!G50/100) -> 22.2906 | H6: =Raw_Data_Quantitative!H66*(1-Raw_Data_Quantitative!H50/100) -> 20.3 | I6: =Raw_Data_Quantitative!I66*(1-Raw_Data_Quantitative!I50/100) -> 0.8955 | J6: =Raw_Data_Quantitative!J66*(1-Raw_Data_Quantitative!J50/100) -> 25.52 | K6: =Raw_Data_Quantitative!K66*(1-Raw_Data_Quantitative!K50/100) -> 103.835 | ... AG6: =Raw_Data_Quantitative!AG66*(1-Raw_Data_Quantitative!AG50/100) -> 10.1924 | AH6: =SUM(D6:AG6) -> 809.452
B7: 2030 clean cooking access gap (million) | D7: =IF(Raw_Data_Quantitative!D58=0,D6,Raw_Data_Quantitative!D67*(1-Raw_Data_Quantitative!D58/100)) -> 8.309411 | E7: =IF(Raw_Data_Quantitative!E58=0,E6,Raw_Data_Quantitative!E67*(1-Raw_Data_Quantitative!E58/100)) -> 0.27659175 | F7: =IF(Raw_Data_Quantitative!F58=0,F6,Raw_Data_Quantitative!F67*(1-Raw_Data_Quantitative!F58/100)) -> 9.7092099 | G7: =IF(Raw_Data_Quantitative!G58=0,G6,Raw_Data_Quantitative!G67*(1-Raw_Data_Quantitative!G58/100)) -> 20.266314 | H7: =IF(Raw_Data_Quantitative!H58=0,H6,Raw_Data_Quantitative!H67*(1-Raw_Data_Quantitative!H58/100)) -> 13.072039 | I7: =IF(Raw_Data_Quantitative!I58=0,I6,Raw_Data_Quantitative!I67*(1-Raw_Data_Quantitative!I58/100)) -> 0.67498515 | J7: =IF(Raw_Data_Quantitative!J58=0,J6,Raw_Data_Quantitative!J67*(1-Raw_Data_Quantitative!J58/100)) -> 18.349504 | K7: =IF(Raw_Data_Quantitative!K58=0,K6,Raw_Data_Quantitative!K67*(1-Raw_Data_Quantitative!K58/100)) -> 92.072541 | ... AG7: =IF(Raw_Data_Quantitative!AG58=0,AG6,Raw_Data_Quantitative!AG67*(1-Raw_Data_Quantitative!AG58/100)) -> 5.5831046 | AH7: =SUM(D7:AG7) -> 411.04683
B8: Clean cooking access gap reduction, 2024-2030 (million) | D8: =D6-D7 -> 4.668089 | E8: =E6-E7 -> 0.55840825 | F8: =F6-F7 -> 4.2907901 | G8: =G6-G7 -> 2.0242863 | H8: =H6-H7 -> 7.2279613 | I8: =I6-I7 -> 0.22051485 | J8: =J6-J7 -> 7.1704955 | K8: =K6-K7 -> 11.762459 | ... AG8: =AG6-AG7 -> 4.6092955 | AH8: =SUM(D8:AG8) -> 398.40517
B9: Clean cooking population increase, 2024-2030 (million) | D9: =(Raw_Data_Quantitative!D67*(Raw_Data_Quantitative!D58/100))-(Raw_Data_Quantitative!D66*(Raw_Data_Quantitative!D50/100)) -> 6.786911 | E9: =(Raw_Data_Quantitative!E67*(Raw_Data_Quantitative!E58/100))-(Raw_Data_Quantitative!E66*(Raw_Data_Quantitative!E50/100)) -> 0.82432575 | F9: =(Raw_Data_Quantitative!F67*(Raw_Data_Quantitative!F58/100))-(Raw_Data_Quantitative!F66*(Raw_Data_Quantitative!F50/100)) -> 6.4728066 | G9: =(Raw_Data_Quantitative!G67*(Raw_Data_Quantitative!G58/100))-(Raw_Data_Quantitative!G66*(Raw_Data_Quantitative!G50/100)) -> 6.7014758 | H9: =(Raw_Data_Quantitative!H67*(Raw_Data_Quantitative!H58/100))-(Raw_Data_Quantitative!H66*(Raw_Data_Quantitative!H50/100)) -> 11.13544 | I9: =(Raw_Data_Quantitative!I67*(Raw_Data_Quantitative!I58/100))-(Raw_Data_Quantitative!I66*(Raw_Data_Quantitative!I50/100)) -> 0.28477935 | J9: =(Raw_Data_Quantitative!J67*(Raw_Data_Quantitative!J58/100))-(Raw_Data_Quantitative!J66*(Raw_Data_Quantitative!J50/100)) -> 11.969504 | K9: =(Raw_Data_Quantitative!K67*(Raw_Data_Quantitative!K58/100))-(Raw_Data_Quantitative!K66*(Raw_Data_Quantitative!K50/100)) -> 33.99466 | ... AG9: =(Raw_Data_Quantitative!AG67*(Raw_Data_Quantitative!AG58/100))-(Raw_Data_Quantitative!AG66*(Raw_Data_Quantitative!AG50/100)) -> 6.6196439 | AH9: =SUM(D9:AG9) -> 541.08234
A12: Electricity Access | B12: Current Electricity Access Rate (%) | C12: M300 National Energy Compacts | D12: 42.6 | E12: 76.6 | F12: 25.9 | G12: 74 | H12: 11 | I12: 95 | J12: 64 | K12: 21.5 | L12: 44 | M12: 73.7 | N12: 89 | O12: 53 | P12: 75 | Q12: 53 | R12: 32.7 | S12: 36 | T12: 25.9 | U12: 55 | V12: 60.1 | W12: 59.5 | X12: 20.84 | Y12: 61 | Z12: 31.66 | AA12: 84 | AB12: 84 | AC12: 36 | AD12: 70 | AE12: 78.4 | AF12: 53.6 | AG12: 62
B13: Target Electricity Access Rate by 2030 (%) | C13: M300 National Energy Compacts | D13: 70 | E13: 100 | F13: 70 | G13: 100 | H13: 90 | I13: 100 | J13: 100 | K13: 62 | L13: 75 | M13: 100 | N13: 99.8 | O13: 100 | P13: 100 | Q13: 100 | R13: 75 | S13: 80 | T13: 70 | U13: 100 | V13: 100 | W13: 70 | X13: 60 | Y13: 100 | Z13: 81.3 | AA13: 100 | AB13: 100 | AC13: 78 | AD13: 100 | AE13: 100 | AF13: 100 | AG13: 100
A14: Clean Cooking | B14: Clean cooking access - current (%) | C14: M300 National Energy Compacts | D14: 10.5 | E14: 66.6 | G14: 23.4 | I14: 0.5 | J14: 20 | K14: 5 | L14: 8 | M14: 25 | N14: 36.9 | O14: 12 | P14: 34.4 | Q14: 45.2 | R14: 0.8 | S14: 14 | T14: 24.5 | U14: 54 | V14: 17 | W14: 48.5 | X14: 6 | Y14: 26 | Z14: 39.6 | AA14: 62 | AC14: 1.5 | AD14: 14 | AE14: 6.9 | AF14: 8.9 | AG14: 38.6
B15: Clean cooking access - 2030 target (%) | C15: M300 National Energy Compacts | D15: 50 | E15: 90 | F15: 40 | G15: 40 | H15: 46 | I15: 30 | J15: 50 | K15: 30 | L15: 57.74 | M15: 50 | N15: 50 | O15: 35 | P15: 100 | Q15: 75 | S15: 50 | T15: 75 | V15: 54 | W15: 61 | X15: 12 | Y15: 100 | Z15: 81.3 | AA15: 75 | AC15: 25 | AD15: 80 | AE15: 75 | AF15: 40 | AG15: 70
A16: Population | B16: 2024 population (million) | C16: World Bank Open Database | D16: 14.5 | E16: 2.5 | F16: 14 | G16: 29.1 | H16: 20.3 | I16: 0.9 | J16: 31.9 | K16: 109.3 | L16: 132.1 | M16: 2.8 | N16: 34.4 | O16: 14.8 | P16: 56.4 | Q16: 2.3 | R16: 5.6 | S16: 32 | T16: 21.7 | U16: 5.2 | V16: 34.6 | W16: 3 | X16: 27 | Y16: 232.7 | Z16: 6.3 | AA16: 0.2 | AB16: 18.5 | AC16: 8.6 | AD16: 9.5 | AE16: 68.6 | AF16: 21.3 | AG16: 16.6
B17: 2030 Projected population (million) | C17: UN World Population Prospects | D17: 16.62 | E17: 2.77 | F17: 16.18 | G17: 33.78 | H17: 24.21 | I17: 0.96 | J17: 36.7 | K17: 131.53 | L17: 152.86 | M17: 3.13 | N17: 38.22 | O17: 16.81 | P17: 63.1 | Q17: 2.49 | R17: 6.37 | S17: 36.69 | T17: 25.16 | U17: 6.06 | V17: 40.85 | W17: 3.39 | X17: 32.52 | Y17: 262.38 | Z17: 7.28 | AA17: 0.26 | AB17: 21.16 | AC17: 9.69 | AD17: 10.79 | AE17: 80.91 | AF17: 25.02 | AG17: 18.61
A18: Generation Capacity & Supply Mix | B18: Installed Capacity – Current (MW) | C18: M300 National Energy Compacts | D18: 199.8 | E18: 892 | F18: 204.88 | G18: 3000 | H18: 487 | I18: 53 | J18: 2907 | K18: 3067 | L18: 9761 | M18: 99 | N18: 5641 | O18: 1310 | P18: 2627 | Q18: 104.7 | R18: 126 | S18: 828 | T18: 550 | U18: 615.1 | V18: 2922 | W18: 695 | X18: 352 | Y18: 12000 | Z18: 748 | AA18: 38 | AC18: 271 | AD18: 267.5 | AE18: 3404.2 | AF18: 3811.3 | AG18: 2962
B19: Installed Capacity – 2030 Target (MW) | C19: M300 National Energy Compacts | D19: 794 | E19: 950 | F19: 410 | G19: 3000 | H19: 866 | J19: 5128 | K19: 13576 | L19: 14000 | N19: 6200 | O19: 3827 | P19: 5952 | T19: 1490 | W19: 1149 | Z19: 3701 | AC19: 1120 | AD19: 1154.5 | AF19: 10000 | AG19: 5432
B20: New Generation Required (MW) | C20: M300 National Energy Compacts | H20: 866 | J20: 1374 | O20: 2517 | P20: 3325 | T20: 848 | V20: 3100 | W20: 454 | Z20: 2953 | AA20: 60 | AD20: 894 | AE20: 1973 | AF20: 6200
A21: Finance | B21: Total Investment Required (USD) | C21: M300 National Energy Compacts | D21: 2360000000 | E21: 2520000000 | F21: 3490000000 | G21: 12554000000 | H21: 1950000000 | I21: 390210000 | J21: 8460000000 | K21: 37048660000 | L21: 9646040000 | M21: 552000000 | N21: 4404000000 | O21: 8900000000 | P21: 19115000000 | Q21: 1970000000 | R21: 1500000000 | S21: 7200000000 | T21: 5500000000 | U21: 3067300000 | V21: 18620000000 | W21: 1764000000 | Y21: 32700000000 | Z21: 11543000000 | AA21: 297000000 | AB21: 6300000000 | AC21: 2245000000 | AD21: 12889999999 | AE21: 3000000000 | AF21: 11880000000 | AG21: 9134890000
B22: Public Financing Required (USD) | C22: M300 National Energy Compacts | D22: 1420000000 | E22: 1414000000 | F22: 1950000000 | H22: 1299744000 | I22: 117000000 | J22: 4620000000 | K22: 17314100000 | L22: 6584240000 | M22: 305000000 | N22: 1793000000 | O22: 1200000000 | P22: 14002000000 | Q22: 499700000 | R22: 1150000000 | S22: 2880000000 | U22: 1220260000 | V22: 9923000000 | W22: 1353000000 | Y22: 17200000000 | Z22: 3276000000 | AA22: 108000000 | AB22: 3926000000 | AC22: 835000000 | AD22: 8850000000 | AE22: 1320000000
B23: Private Financing Required (USD) | C23: M300 National Energy Compacts | D23: 940000000 | E23: 1106000000 | F23: 1540000000 | G23: 6372000000 | H23: 650256000 | I23: 273000000 | J23: 1940000000 | K23: 19734550000 | L23: 3061800000 | M23: 247000000 | N23: 2611000000 | O23: 7641000000 | P23: 5113000000 | Q23: 1470000000 | R23: 140000000 | S23: 4320000000 | T23: 162800000 | U23: 1225800000 | V23: 8698000000 | W23: 411000000 | X23: 527000000 | Y23: 15500000000 | Z23: 8267000000 | AA23: 190000000 | AB23: 2300000000 | AC23: 1410000000 | AD23: 4039000000 | AE23: 1680000000 | AF23: 9500000000 | AG23: 4420000000
B25: 2024 population with electricity access (million) | D25: =D16*(D12/100) -> 6.177 | E25: =E16*(E12/100) -> 1.915 | F25: =F16*(F12/100) -> 3.626 | G25: =G16*(G12/100) -> 21.534 | H25: =H16*(H12/100) -> 2.233 | I25: =I16*(I12/100) -> 0.855 | J25: =J16*(J12/100) -> 20.416 | K25: =K16*(K12/100) -> 23.4995 | ... AG25: =AG16*(AG12/100) -> 10.292
B26: 2030 population with electricity access (million) | D26: =D17*(D13/100) -> 11.634 | E26: =E17*(E13/100) -> 2.77 | F26: =F17*(F13/100) -> 11.326 | G26: =G17*(G13/100) -> 33.78 | H26: =H17*(H13/100) -> 21.789 | I26: =I17*(I13/100) -> 0.96 | J26: =J17*(J13/100) -> 36.7 | K26: =K17*(K13/100) -> 81.5486 | ... AG26: =AG17*(AG13/100) -> 18.61
B27: 2024 population with clean cooking access (million) | D27: =IF(ISBLANK(D14),"",D16*(D14/100)) -> 1.5225 | E27: =IF(ISBLANK(E14),"",E16*(E14/100)) -> 1.665 | F27: =IF(ISBLANK(F14),"",F16*(F14/100)) | G27: =IF(ISBLANK(G14),"",G16*(G14/100)) -> 6.8094 | H27: =IF(ISBLANK(H14),"",H16*(H14/100)) | I27: =IF(ISBLANK(I14),"",I16*(I14/100)) -> 0.0045 | J27: =IF(ISBLANK(J14),"",J16*(J14/100)) -> 6.38 | K27: =IF(ISBLANK(K14),"",K16*(K14/100)) -> 5.465 | ... AG27: =IF(ISBLANK(AG14),"",AG16*(AG14/100)) -> 6.4076
B28: 2030 population with clean cooking access (million) | D28: =IF(ISBLANK(D15),D17*(D14/100),D17*(D15/100)) -> 8.31 | E28: =IF(ISBLANK(E15),E17*(E14/100),E17*(E15/100)) -> 2.493 | F28: =IF(ISBLANK(F15),F17*(F14/100),F17*(F15/100)) -> 6.472 | G28: =IF(ISBLANK(G15),G17*(G14/100),G17*(G15/100)) -> 13.512 | H28: =IF(ISBLANK(H15),H17*(H14/100),H17*(H15/100)) -> 11.1366 | I28: =IF(ISBLANK(I15),I17*(I14/100),I17*(I15/100)) -> 0.288 | J28: =IF(ISBLANK(J15),J17*(J14/100),J17*(J15/100)) -> 18.35 | K28: =IF(ISBLANK(K15),K17*(K14/100),K17*(K15/100)) -> 39.459 | ... AG28: =IF(ISBLANK(AG15),AG17*(AG14/100),AG17*(AG15/100)) -> 13.027
B29: Electricity access population increase, 2024-2030 (million) | D29: =D26-D25 -> 5.457 | E29: =E26-E25 -> 0.855 | F29: =F26-F25 -> 7.7 | G29: =G26-G25 -> 12.246 | H29: =H26-H25 -> 19.556 | I29: =I26-I25 -> 0.105 | J29: =J26-J25 -> 16.284 | K29: =K26-K25 -> 58.0491 | ... AG29: =AG26-AG25 -> 8.318 | AH29: =SUM(D29:AG29) -> 474.62272
B30: Clean cooking population increase, 2024-2030 (million) | D30: =D28-D27 -> 6.7875 | E30: =E28-E27 -> 0.828 | F30: =F28-F27 -> #VALUE! | G30: =G28-G27 -> 6.7026 | H30: =H28-H27 -> #VALUE! | I30: =I28-I27 -> 0.2835 | J30: =J28-J27 -> 11.97 | K30: =K28-K27 -> 33.994 | ... AG30: =AG28-AG27 -> 6.6194 | AH30: =SUM(D30:AG30) -> #VALUE!
B31: 2024 electricity access gap, population (million) | D31: =D16-(D16*(D12/100)) -> 8.323 | E31: =E16-(E16*(E12/100)) -> 0.585 | F31: =F16-(F16*(F12/100)) -> 10.374 | G31: =G16-(G16*(G12/100)) -> 7.566 | H31: =H16-(H16*(H12/100)) -> 18.067 | I31: =I16-(I16*(I12/100)) -> 0.045 | J31: =J16-(J16*(J12/100)) -> 11.484 | K31: =K16-(K16*(K12/100)) -> 85.8005 | ... AG31: =AG16-(AG16*(AG12/100)) -> 6.308
B32: 2030 electricity access gap, population (million) | D32: =D17-(D17*(D13/100)) -> 4.986 | E32: =E17-(E17*(E13/100)) -> 0 | F32: =F17-(F17*(F13/100)) -> 4.854 | G32: =G17-(G17*(G13/100)) -> 0 | H32: =H17-(H17*(H13/100)) -> 2.421 | I32: =I17-(I17*(I13/100)) -> 0 | J32: =J17-(J17*(J13/100)) -> 0 | K32: =K17-(K17*(K13/100)) -> 49.9814 | ... AG32: =AG17-(AG17*(AG13/100)) -> 0
B33: 2024 clean cooking access gap, population (million) | D33: =IF(ISBLANK(D14),"",(D16-D27)) -> 12.9775 | E33: =IF(ISBLANK(E14),"",(E16-E27)) -> 0.835 | F33: =IF(ISBLANK(F14),"",(F16-F27)) | G33: =IF(ISBLANK(G14),"",(G16-G27)) -> 22.2906 | H33: =IF(ISBLANK(H14),"",(H16-H27)) | I33: =IF(ISBLANK(I14),"",(I16-I27)) -> 0.8955 | J33: =IF(ISBLANK(J14),"",(J16-J27)) -> 25.52 | K33: =IF(ISBLANK(K14),"",(K16-K27)) -> 103.835 | ... AG33: =IF(ISBLANK(AG14),"",(AG16-AG27)) -> 10.1924
B34: 2030 clean cooking access gap, population (million) | D34: =IF(ISBLANK(D15),"",(D17-D28)) -> 8.31 | E34: =IF(ISBLANK(E15),"",(E17-E28)) -> 0.277 | F34: =IF(ISBLANK(F15),"",(F17-F28)) -> 9.708 | G34: =IF(ISBLANK(G15),"",(G17-G28)) -> 20.268 | H34: =IF(ISBLANK(H15),"",(H17-H28)) -> 13.0734 | I34: =IF(ISBLANK(I15),"",(I17-I28)) -> 0.672 | J34: =IF(ISBLANK(J15),"",(J17-J28)) -> 18.35 | K34: =IF(ISBLANK(K15),"",(K17-K28)) -> 92.071 | ... AG34: =IF(ISBLANK(AG15),"",(AG17-AG28)) -> 5.583
B35: Electricity access gap decrease, population, 2024-2030 (million) | D35: =IF(D31="","",(D31-D32)) -> 3.337 | E35: =IF(E31="","",(E31-E32)) -> 0.585 | F35: =IF(F31="","",(F31-F32)) -> 5.52 | G35: =IF(G31="","",(G31-G32)) -> 7.566 | H35: =IF(H31="","",(H31-H32)) -> 15.646 | I35: =IF(I31="","",(I31-I32)) -> 0.045 | J35: =IF(J31="","",(J31-J32)) -> 11.484 | K35: =IF(K31="","",(K31-K32)) -> 35.8191 | ... AG35: =IF(AG31="","",(AG31-AG32)) -> 6.308 | AH35: =SUM(D35:AG35) -> 324.82272
B36: Clean cooking access gap decrease, population, 2024-2030 (million) | D36: =IF(D33="","",(D33-D34)) -> 4.6675 | E36: =IF(E33="","",(E33-E34)) -> 0.558 | F36: =IF(F33="","",(F33-F34)) | G36: =IF(G33="","",(G33-G34)) -> 2.0226 | H36: =IF(H33="","",(H33-H34)) | I36: =IF(I33="","",(I33-I34)) -> 0.2235 | J36: =IF(J33="","",(J33-J34)) -> 7.17 | K36: =IF(K33="","",(K33-K34)) -> 11.764 | ... AG36: =IF(AG33="","",(AG33-AG34)) -> 4.6094 | AH36: =SUM(D36:AG36) -> #VALUE!
B38: Investment per MW, investment intensity (USD/MW) | D38: =IF(ISBLANK(D20),"",(D21/D20)) | E38: =IF(ISBLANK(E20),"",(E21/E20)) | F38: =IF(ISBLANK(F20),"",(F21/F20)) | G38: =IF(ISBLANK(G20),"",(G21/G20)) | H38: =IF(ISBLANK(H20),"",(H21/H20)) -> 2251732.1 | I38: =IF(ISBLANK(I20),"",(I21/I20)) | J38: =IF(ISBLANK(J20),"",(J21/J20)) -> 6157205.2 | K38: =IF(ISBLANK(K20),"",(K21/K20)) | ... AG38: =IF(ISBLANK(AG20),"",(AG21/AG20))
B39: MW per investment, investment efficiency (MW/USD) | D39: =IF(ISBLANK(D20),"",(D20/D21)) | E39: =IF(ISBLANK(E20),"",(E20/E21)) | F39: =IF(ISBLANK(F20),"",(F20/F21)) | G39: =IF(ISBLANK(G20),"",(G20/G21)) | H39: =IF(ISBLANK(H20),"",(H20/H21)) -> 4.4410256e-07 | I39: =IF(ISBLANK(I20),"",(I20/I21)) | J39: =IF(ISBLANK(J20),"",(J20/J21)) -> 1.6241135e-07 | K39: =IF(ISBLANK(K20),"",(K20/K21)) | ... AG39: =IF(ISBLANK(AG20),"",(AG20/AG21))
B40: MW per investment, investment efficiency (MW/USD billion) | D40: =IF(ISBLANK(D20),"",(D20/D21)*1000000000) | E40: =IF(ISBLANK(E20),"",(E20/E21)*1000000000) | F40: =IF(ISBLANK(F20),"",(F20/F21)*1000000000) | G40: =IF(ISBLANK(G20),"",(G20/G21)*1000000000) | H40: =IF(ISBLANK(H20),"",(H20/H21)*1000000000) -> 444.10256 | I40: =IF(ISBLANK(I20),"",(I20/I21)*1000000000) | J40: =IF(ISBLANK(J20),"",(J20/J21)*1000000000) -> 162.41135 | K40: =IF(ISBLANK(K20),"",(K20/K21)*1000000000) | ... AG40: =IF(ISBLANK(AG20),"",(AG20/AG21)*1000000000)
A42: Row 29 | B42: Current electricity access gap (million)
A43: Row 30 | B43: 2030 electricity access gap (million)
A44: Row 35 | B44: Electricity access gap reduction, 2024-2030 (million)
A45: Row 26 | B45: Electricity access population increase, 2024-2030 (million)
...

Sheet Raw_Data_Quantitative
A1: Category | B1: Indicator | C1: Data Source | D1: Benin | E1: Botswana | F1: Burundi | G1: Cameroon | H1: Chad | I1: Comoros | J1: Côte d’Ivoire | K1: Democratic Republic of Congo | L1: Ethiopia | M1: Gambia | N1: Ghana | O1: Guinea | P1: Kenya | Q1: Lesotho | R1: Liberia | S1: Madagascar | T1: Malawi | U1: Mauritania | V1: Mozambique | W1: Namibia | X1: Niger | Y1: Nigeria | Z1: Republic of Congo | AA1: São Tomé & Príncipe | AB1: Senegal | AC1: Sierra Leone | AD1: Togo | AE1: Tanzania | AF1: Zambia | AG1: Zimbabwe
A2: Electricity Access | B2: Current Electricity Access Rate (%) | C2: M300 National Energy Compacts | D2: 42.6 | E2: 76.6 | F2: 25.9 | G2: 74 | H2: 11 | J2: 64 | K2: 21.5 | L2: 44 | M2: 73.7 | N2: 89 | O2: 53 | P2: 75 | Q2: 53 | R2: 32.7 | S2: 36 | T2: 25.9 | U2: 55 | V2: 60.1 | W2: 59.5 | X2: 20.84 | Y2: 61 | Z2: 31.66 | AA2: 84 | AB2: 84 | AC2: 36 | AD2: 70 | AE2: 78.4 | AF2: 53.6 | AG2: 62
B3: Current Urban Electricity Access Rate (%) | C3: M300 National Energy Compacts | D3: 71.2 | F3: 66.3 | G3: 94 | H3: 20 | O3: 89 | Q3: 71.3 | S3: 72 | T3: 56.5 | U3: 91 | W3: 77.1 | Z3: 38.67 | AB3: 97.1 | AE3: 99.6 | AF3: 80.3 | AG3: 83
B4: Current Rural Electricity Access Rate (%) | C4: M300 National Energy Compacts | D4: 13.1 | F4: 17.6 | G4: 25 | H4: 1 | O4: 21 | Q4: 11.4 | S4: 11 | T4: 3.8 | U4: 6 | W4: 13.8 | X4: 5.3 | Z4: 1.01 | AB4: 64.5 | AE4: 69.6 | AF4: 34.9 | AG4: 27
B5: Target Electricity Access Rate by 2030 (%) | C5: M300 National Energy Compacts | D5: 70 | E5: 100 | F5: 70 | G5: 100 | H5: 90 | I5: 100 | J5: 100 | K5: 62 | L5: 75 | M5: 100 | N5: 99.8 | O5: 100 | P5: 100 | Q5: 100 | R5: 75 | S5: 80 | T5: 70 | U5: 100 | V5: 100 | W5: 70 | X5: 60 | Y5: 100 | Z5: 81.3 | AA5: 100 | AB5: 100 | AC5: 78 | AD5: 100 | AE5: 100 | AF5: 100 | AG5: 100
B6: Target Urban Electricity Access Rate by 2030 (%) | C6: M300 National Energy Compacts | H6: 50 | Z6: 90
B7: Target Rural Electricity Access Rate by 2030 (%) | C7: M300 National Energy Compacts | H7: 40 | Z7: 50
B8: Population Without Electricity (people) | C8: M300 National Energy Compacts | F8: 11600000 | H8: 14000000 | K8: 60000000 | M8: 633000 | N8: 3700000 | O8: 7750000 | S8: 19000000 | U8: 3400000 | Y8: 86000000 | AB8: 2800000
A9: Generation Capacity & Supply Mix | B9: Installed Capacity – Current (MW) | C9: M300 National Energy Compacts | D9: 199.8 | E9: 892 | F9: 204.88 | H9: 487 | I9: 53 | J9: 2907 | K9: 3067 | L9: 9761 | M9: 99 | N9: 5641 | O9: 1310 | Q9: 104.7 | R9: 126 | S9: 828 | T9: 550 | U9: 615.1 | V9: 2922 | W9: 695 | X9: 352 | Z9: 748 | AA9: 38 | AC9: 271 | AD9: 267.5 | AE9: 3404.2 | AF9: 3811.3 | AG9: 2962
B10: Installed Capacity – 2030 Target (MW) | C10: M300 National Energy Compacts | D10: 794 | E10: 950 | F10: 410 | G10: 3000 | H10: 866 | J10: 5128 | K10: 13576 | L10: 14000 | N10: 6200 | O10: 3827 | P10: 5952 | T10: 1490 | W10: 1149 | Z10: 3701 | AC10: 1120 | AD10: 1154.5 | AF10: 10000 | AG10: 5432
B11: New Generation Required (MW) | C11: M300 National Energy Compacts | H11: 866 | J11: 1374 | O11: 2517 | T11: 848 | V11: 3100 | W11: 454 | Z11: 2953 | AA11: 60 | AD11: 894 | AE11: 1973 | AF11: 6200 | AH11: =COUNT(D11:AG11) -> 11
B12: Renewable Capacity – Current (MW) | C12: M300 National Energy Compacts | D12: 62.3 | E12: 74.6 | G12: 36.53 | I12: =13+0.712 -> 13.712 | J12: 909 | N12: 60.8 | V12: =2193+98 -> 2291 | W12: 498.5 | Z12: 214 | AB12: 460 | AD12: 102.5 | AE12: 2011.27 | AF12: 3336 | AG12: 1282
B13: Renewable Capacity – 2030 Target (MW) | C13: M300 National Energy Compacts | D13: 417 | E13: 475 | H13: 520 | J13: 2283 | V13: =4344+303+245 -> 4892 | W13: 952.5 | Z13: 2697 | AD13: 728.5 | AF13: 9000 | AG13: 2640
B14: Solar Capacity Target (MW) | C14: M300 National Energy Compacts | E14: 1500 | G14: 150 | H14: 520 | J14: 399 | K14: 4000 | L14: 1175 | M14: 150 | N14: 850 | O14: 1086 | P14: 807 | R14: 172 | S14: 560 | V14: 303 | W14: 466.5 | AA14: 30 MWp | AC14: 392 | AD14: 569 | AE14: 463 | AF14: 3000
B15: Wind Capacity Target (MW) | C15: M300 National Energy Compacts | E15: 100 | L15: 1102 | N15: 200 | P15: 966 | Q15: 60 | V15: 245 | W15: 99 | X15: 250 | AE15: 500 | AF15: 1192
B16: Hydro Capacity Target (MW) | C16: M300 National Energy Compacts | J16: 829 | L16: 1800 | N16: 150 | O16: 791 | P16: 1403 | R16: 150 | V16: 4344 | W16: 347 | X16: 128 | AA16: 9 | AC16: 194 | AD16: 57 | AE16: 880
B17: Gas Capacity Target (MW) | C17: M300 National Energy Compacts | M17: 80 | U17: 225 | V17: 1004 | X17: 240 | Z17: 470 | AA17: 10 | AB17: 2200 | AD17: 250
B18: Battery Storage Target (MWh) | C18: M300 National Energy Compacts | M18: 40 | P18: 400 | Q18: 600 | R18: 5 | U18: 30 | W18: 96 | X18: 20 | AD18: 156
A19: Demand | B19: Peak Demand – Current (MW) | C19: M300 National Energy Compacts | E19: 678 | I19: 26.2 | Q19: 209 | R19: 108 | W19: 673 | AE19: 1888.72 | AF19: 2500 | AG19: 2000
B20: Peak Demand – 2030 (MW) | C20: M300 National Energy Compacts | T20: 774
A21: Networks & Losses | B21: Transmission Lines – Existing (km) | C21: M300 National Energy Compacts | D21: 1449.1 | E21: 4000 | F21: 650 | H21: 996 | J21: 7553 | L21: 20390 | N21: 6472.2 | O21: 1600 | P21: 9484 | T21: 2650 | U21: 1950 | V21: 5679 | X21: 1428.8 | Y21: =5530+6800 -> 12330 | Z21: =1256+500 -> 1756 | AA21: 275 | AC21: 802 | AD21: 1273 | AE21: 8025.75 | AF21: 12705
B22: Transmission Lines – Added (km) | C22: M300 National Energy Compacts | F22: 704 | H22: 400.2 | M22: 200 | O22: 352 | P22: 8000 | T22: 1940 | AC22: 1235 | AD22: 1447 | AG22: 1607
B23: Distribution Lines – Added (km) | C23: M300 National Energy Compacts | F23: 6578 | H23: 195 | P23: 212937 | Q23: 550 | T23: 22417 | AD23: 3761
B24: System Losses – Current (%) | C24: M300 National Energy Compacts | D24: 24.62 | E24: 14.35 | H24: 39 | I24: 37 | K24: 46 | L24: 27 | M24: 21 | N24: 27 | O24: 30 | P24: =4.5+11.19 -> 15.69 | R24: 45.4 | U24: 30 | V24: 24 | Y24: 42 | Z24: 45 | AA24: 34 | AC24: 50 | AD24: 16 | AE24: 14.2
B25: System Losses – Target (%) | C25: M300 National Energy Compacts | D25: 15 | H25: 15 | I25: 20 | K25: 15 | L25: 19 | M25: 18 | N25: 23 | O25: 8 | P25: =3.5+9.3 -> 12.8 | S25: 16 | AA25: 18 | AD25: 12
A26: Connections | B26: Grid Connections – New (connections) | C26: M300 National Energy Compacts | D26: 928 | E26: 220000 | F26: 1900000 | I26: 62310 | P26: 5100000 | Q26: 26400 | T26: 1150000 | V26: 4900000 | X26: 2077515 | Y26: 4700000 | Z26: 953000 | AB26: 260149 | AD26: 1300000 | AF26: 1459560 | AG26: 1200000
B27: Grid Connections – New (HH) | C27: M300 National Energy Compacts | N27: 660000 | W27: 175000 | AC27: 160000 | AE27: 8300000
B28: Off-grid Connections Target (connections) | C28: M300 National Energy Compacts | E28: 61000 | F28: 410000 | Q28: 18900 | T28: 1550000 | AD28: 133000 | AF28: 1768311 | AG28: 1500000
B29: Off-grid Connections Target (Mini-grids) | C29: M300 National Energy Compacts | X29: 115301
B30: Off-grid Connections Target (Solar kits) | C30: M300 National Energy Compacts | X30: 690392
B31: Off-grid Connections Target (HH) | C31: M300 National Energy Compacts | W31: 35000 | AA31: 800 | AC31: 560000
B32: Mini-grid Sites Target (count) | C32: M300 National Energy Compacts | E32: 6 | F32: 300 | N32: 400 | O32: 714 | U32: 120 | X32: 115301 | AB32: 150
B33: Mini-grid Capacity Target (MW) | C33: M300 National Energy Compacts | F33: 300 | AB33: 50
B34: SHS Connections Target (connections) | C34: M300 National Energy Compacts | F34: 850000 | H34: 30000 | N34: 1000000 | R34: 49441 | T34: 244000 | V34: 175235 | X34: 690392 | AB34: 300000 | AC34: 400000 | AD34: 133000
A35: Finance | B35: Total Investment Required (USD) | C35: M300 National Energy Compacts | D35: 2360000000 | E35: 2520000000 | F35: 3490000000 | G35: 12554000000 | H35: 1950000000 | I35: 390210000 | J35: 8460000000 | K35: 37048660000 | L35: 9646040 | M35: 552000000 | N35: 4404000000 | O35: 8900000000 | P35: 19115000000 | Q35: 1970000000 | R35: 1500000000 | S35: 7200000000 | T35: 5500000000 | U35: 3067300000 | V35: 18620000000 | W35: 1764000000 | Y35: 32700000000 | Z35: 11543000000 | AA35: 297000000 | AB35: 6300000000 | AC35: 2245000000 | AD35: 3000000000 | AE35: 12889999999 | AF35: 11880000 | AG35: 9134890000
B36: Public Financing Required (USD) | C36: M300 National Energy Compacts | D36: 1420000000 | E36: 1414000000 | F36: 1950000000 | G36: 1588000000 | H36: 1299744000 | I36: 117000000 | J36: 4620000000 | K36: 17314100000 | L36: 6584240 | M36: 305000000 | N36: 1793000 | O36: 1200000000 | P36: 14002000000 | Q36: 499700000 | R36: 1150000000 | U36: 1220260000 | V36: 9923000000 | W36: 1353000000 | Y36: 17200000000 | Z36: 3276000000 | AA36: 108000000 | AB36: 3926000000 | AC36: 835000000 | AD36: 1320000000 | AE36: 8850000000
B37: Private Financing Required (USD) | C37: M300 National Energy Compacts | D37: 940000000 | E37: 1106000000 | F37: 1540000000 | G37: 6372000000 | H37: 650256000 | I37: 273000000 | J37: 1940000000 | K37: 19734550000 | L37: 3061800 | M37: 247000000 | N37: 2611000 | O37: 7641000000 | P37: 5113000000 | Q37: 1470000000 | R37: 140000000 | T37: 162800000 | U37: 1225800000 | V37: 8698000000 | W37: 411000000 | X37: 527000000 | Y37: 15500000000 | Z37: 8267000000 | AA37: 190000000 | AB37: 2300000000 | AC37: 1410000000 | AD37: 1680000000 | AE37: 4039000000 | AF37: 9500000000 | AG37: 4420000000
B38: World Bank Financing (USD) | C38: M300 National Energy Compacts | N38: 260000000 | Q38: 52900000 | R38: 200000000
B39: AfDB Financing (USD) | C39: M300 National Energy Compacts | N39: 85000000 | Q39: 10600000
B40: Other Donor Financing (USD) | C40: M300 National Energy Compacts | I40: 101400000 | T40: 530800000 | U40: 621240000
...

Sheet Qualitative
A1: Scoring legend:
A2: 0 = Not mentioned
A3: 1 = Mentioned
A4: 2 = Operationalised (actions, reforms, or institutions named)
B5: Benin | C5: Botswana | D5: Burundi | E5: Cameroon | F5: Chad | G5: Comoros | H5: Côte d’Ivoire | I5: DRC | J5: Ethiopia | K5: Gambia | L5: Ghana | M5: Guinea | N5: Kenya | O5: Lesotho | P5: Liberia | Q5: Madagascar | R5: Malawi | S5: Mauritania | T5: Mozambique | U5: Namibia | V5: Niger | W5: Nigeria | X5: Republic of Congo | Y5: São Tomé & Príncipe | Z5: Senegal | AA5: Sierra Leone | AB5: Togo | AC5: Tanzania | AD5: Zambia | AE5: Zimbabwe
A6: National definition of electricity access stated | B6: 2
A7: National definition of electricity access stated | B7: 2
A8: Alignment with SDG 7 electricity access definition | B8: 2
A9: Treatment of reliability and quality of electricity supply | B9: 1
A10: Recognition of suppressed or latent electricity demand | B10: 2
A11: Explicit rationale for urban–rural access differentiation | B11: 2
A12: Priority regions or populations explicitly identified | B12: 1
A13: Integration of population growth assumptions in access planning | B13: 1
A14: Consideration of productive-use electricity demand | B14: 2
A15: Explicit prioritisation between grid, mini-grid, and off-grid solutions | B15: 2
A16: Use of least-cost or geospatial electrification planning | B16: 2
A17: Assumptions underpinning installed capacity expansion targets | B17: 2
... A55: Explicit risks and implementation constraints acknowledged | B55: 2
A56: Overall realism and credibility of stated targets

Sheet Qual_Ref
B2: Benin | C2: Botswana | D2: Burundi | E2: Cameroon | F2: Chad | G2: Comoros | H2: Côte d’Ivoire | I2: DRC | J2: Ethiopia | K2: Gambia | L2: Ghana | M2: Guinea | N2: Kenya | O2: Lesotho | P2: Liberia | Q2: Madagascar | R2: Malawi | S2: Mauritania | T2: Mozambique | U2: Namibia | V2: Niger | W2: Nigeria | X2: Republic of Congo | Y2: São Tomé & Príncipe | Z2: Senegal | AA2: Sierra Leone | AB2: Togo | AC2: Tanzania | AD2: Zambia | AE2: Zimbabwe
A3: National definition of electricity access stated | B3: Defines access as “ensemble des ménages ayant accès à l’électricité intégrant les raccordements au réseau, les mini-réseaux et les kits” (footnote defining access; p.2).
A4: National definition of electricity access stated | B4: Explicit alignment with ODD 7 and definition of reliable, affordable, modern energy (p.2).
A5: Alignment with SDG 7 electricity access definition | B5: Repeated use of “électricité fiable, abordable et suffisante” and operational actions: SCADA, smart meters, storage, loss reduction (pp.6–8, 17–25).
A6: Treatment of reliability and quality of electricity supply | B6: Implicit via references to rising demand from mobility, cooking, and growth, but not framed as “suppressed demand” (Table 5, p.15).
A7: Recognition of suppressed or latent electricity demand | B7: Explicit last-mile focus, rural electrification funds (FERER), mini-grids and SHS for off-grid areas (Pillar III).
A8: Explicit rationale for urban–rural access differentiation | B8: Regional breakdowns (Zone Sud / Zone Nord) and rural/off-grid households identified for programmes (pp.17–18).
A9: Priority regions or populations explicitly identified | B9: Population numbers used for access targets, but growth dynamics not explicitly modelled (Table 2, p.11).
A10: Integration of population growth assumptions in access planning | B10: Mention of mobility, industry, and economic growth drivers without explicit PUE strategy (Table 5, p.15).
A11: Consideration of productive-use electricity demand | B11: Clear quantitative targets by modality (Table 3, p.12).
A12: Explicit prioritisation between grid, mini-grid, and off-grid solutions | B12: Explicit use of SIG électrique and geospatial prioritisation (pp.16–18).
A13: Use of least-cost or geospatial electrification planning | B13: Detailed MW targets for solar, thermal, storage, and timelines (pp.15–16).
A14: Assumptions underpinning installed capacity expansion targets | B14: Renewables for sustainability; thermal for reliability and baseload (Pillars I–II).
... A52: Explicit risks and implementation constraints acknowledged | B52: Detailed targets, financing, institutions → high credibility.
A53: Overall realism and credibility of stated targets

Sheet Source_Data
A1: Country | B1: Indicator | C1: Value (as stated in National Energy Compact) | D1: Status | E1: Notes
A2: Benin | B2: Current Electricity Access Rate (%) | C2: 42.6% (2024) | D2: ✅ Fully usable
A3: Benin | B3: Current Urban Electricity Access Rate (%) | C3: 0.712 | D3: ✅ Fully usable
A4: Benin | B4: Current Rural Electricity Access Rate (%) | C4: 0.131 | D4: ✅ Fully usable
A5: Benin | B5: Target Electricity Access Rate by 2030 (%) | C5: 0.7 | D5: ✅ Fully usable
A6: Benin | B6: Target Urban Electricity Access Rate by 2030 (%) | C6: Not stated | D6: ❌ Completely absent
A7: Benin | B7: Target Rural Electricity Access Rate by 2030 (%) | C7: Not stated | D7: ❌ Completely absent
A8: Benin | B8: Population Without Electricity (people) | C8: Not stated | D8: ⚠️ Implicitly referenced
A9: Benin | B9: Installed Capacity – Current (MW) | C9: 199 MW | D9: ✅ Fully usable
A10: Benin | B10: Installed Capacity – 2030 Target (MW) | C10: 794 MW | D10: ✅ Fully usable
